Workbook

Sheet customers
A1: customer_id | B1: customer_name | C1: gender | D1: age | E1: home_address | F1: zip_code | G1: city | H1: state | I1: country
A2: 1 | B2: Leanna Busson | C2: Female | D2: 30 | E2: 8606 Victoria TerraceSuite 560 | F2: 5464 | G2: Johnstonhaven | H2: Northern Territory | I2: Australia
A3: 2 | B3: Zabrina Harrowsmith | C3: Genderfluid | D3: 69 | E3: 8327 Kirlin SummitApt. 461 | F3: 8223 | G3: New Zacharyfort | H3: South Australia | I3: Australia
A4: 3 | B4: Shina Dullaghan | C4: Polygender | D4: 59 | E4: 269 Gemma SummitSuite 109 | F4: 5661 | G4: Aliburgh | H4: Australian Capital Territory | I4: Australia
A5: 4 | B5: Hewet McVitie | C5: Bigender | D5: 67 | E5: 743 Bailey GroveSuite 141 | F5: 1729 | G5: South Justinhaven | H5: Queensland | I5: Australia
A6: 5 | B6: Rubia Ashleigh | C6: Polygender | D6: 30 | E6: 48 Hyatt ManorSuite 375 | F6: 4032 | G6: Griffithsshire | H6: Queensland | I6: Australia
A7: 6 | B7: Cordey Tolcher | C7: Genderfluid | D7: 40 | E7: 7118 Mccullough SquareSuite 639 | F7: 9996 | G7: Blakehaven | H7: New South Wales | I7: Australia
A8: 7 | B8: Winslow Ewbanck | C8: Bigender | D8: 76 | E8: 92 Hills Station StApt. 683 | F8: 793 | G8: Masonfurt | H8: Queensland | I8: Australia
A9: 8 | B9: Marlowe Wynn | C9: Agender | D9: 75 | E9: 383 Muller SummitSuite 809 | F9: 7681 | G9: Samside | H9: Northern Territory | I9: Australia
A10: 9 | B10: Brittaney Gontier | C10: Male | D10: 51 | E10: 57 Greenfelder HillApt. 077 | F10: 2 | G10: Beierport | H10: Northern Territory | I10: Australia
A11: 10 | B11: Susanetta Wilshin | C11: Bigender | D11: 70 | E11: 615 Hayley KnollSuite 454 | F11: 2118 | G11: Joelburgh | H11: Western Australia | I11: Australia
A12: 11 | B12: Michaeline McIndrew | C12: Agender | D12: 39 | E12: 96 Daniel PlaceSuite 898 | F12: 7400 | G12: Georgeland | H12: Northern Territory | I12: Australia
A13: 12 | B13: Fedora Dmych | C13: Bigender | D13: 78 | E13: 66 Kayla MewsSuite 951 | F13: 6334 | G13: Taylorburgh | H13: South Australia | I13: Australia
... A1001: 1000 | B1001: Mandel Fairbanks | C1001: Male | D1001: 71 | E1001: 1671 Lauren KnollSuite 945 | F1001: 9012 | G1001: Lake Audreyborough | H1001: Tasmania | I1001: Australia

Sheet orders
A1: order_id | B1: customer_id | C1: payment | D1: order_date | E1: delivery_date | F1: Gender | G1: Age | H1: State | I1: City
A2: 1 | B2: 64 | C2: 30811 | D2: 44438 | E2: 44463 | F2: =VLOOKUP(B2, customers!A:D, 3, FALSE) -> Genderfluid | G2: =VLOOKUP(B2, customers!A:D, 4, FALSE) -> 75 | H2: =VLOOKUP(B2, customers!A:H, 8, FALSE) -> South Australia | I2: =VLOOKUP(B2, customers!A:H, 7, FALSE) -> Sanfordborough
A3: 2 | B3: 473 | C3: 50490 | D3: 44230 | E3: 44240 | F3: =VLOOKUP(B3, customers!A:D, 3, FALSE) -> Male | G3: =VLOOKUP(B3, customers!A:D, 4, FALSE) -> 61 | H3: =VLOOKUP(B3, customers!A:H, 8, FALSE) -> South Australia | I3: =VLOOKUP(B3, customers!A:H, 7, FALSE) -> Annaton | O3: order_date | P3: SUM of payment
A4: 3 | B4: 774 | C4: 46763 | D4: 44477 | E4: 44503 | F4: =VLOOKUP(B4, customers!A:D, 3, FALSE) -> Genderqueer | G4: =VLOOKUP(B4, customers!A:D, 4, FALSE) -> 34 | H4: =VLOOKUP(B4, customers!A:H, 8, FALSE) -> Tasmania | I4: =VLOOKUP(B4, customers!A:H, 7, FALSE) -> West Jonathanshire | O4: Jan | P4: 3520014
A5: 4 | B5: 433 | C5: 39782 | D5: 44322 | E5: 44335 | F5: =VLOOKUP(B5, customers!A:D, 3, FALSE) -> Non-binary | G5: =VLOOKUP(B5, customers!A:D, 4, FALSE) -> 46 | H5: =VLOOKUP(B5, customers!A:H, 8, FALSE) -> Tasmania | I5: =VLOOKUP(B5, customers!A:H, 7, FALSE) -> West Michaelport | O5: Feb | P5: 3190783
A6: 5 | B6: 441 | C6: 14719 | D6: 44278 | E6: 44279 | F6: =VLOOKUP(B6, customers!A:D, 3, FALSE) -> Bigender | G6: =VLOOKUP(B6, customers!A:D, 4, FALSE) -> 53 | H6: =VLOOKUP(B6, customers!A:H, 8, FALSE) -> Western Australia | I6: =VLOOKUP(B6, customers!A:H, 7, FALSE) -> South Rileyview | O6: Mar | P6: 4129045
A7: 6 | B7: 800 | C7: 16197 | D7: 44448 | E7: 44474 | F7: =VLOOKUP(B7, customers!A:D, 3, FALSE) -> Bigender | G7: =VLOOKUP(B7, customers!A:D, 4, FALSE) -> 49 | H7: =VLOOKUP(B7, customers!A:H, 8, FALSE) -> Queensland | I7: =VLOOKUP(B7, customers!A:H, 7, FALSE) -> Daughertyport | O7: Apr | P7: 3233260
A8: 7 | B8: 626 | C8: 37666 | D8: 44291 | E8: 44297 | F8: =VLOOKUP(B8, customers!A:D, 3, FALSE) -> Genderqueer | G8: =VLOOKUP(B8, customers!A:D, 4, FALSE) -> 64 | H8: =VLOOKUP(B8, customers!A:H, 8, FALSE) -> New South Wales | I8: =VLOOKUP(B8, customers!A:H, 7, FALSE) -> Walterstad | O8: May | P8: 3028007
A9: 8 | B9: 58 | C9: 28484 | D9: 44298 | E9: 44317 | F9: =VLOOKUP(B9, customers!A:D, 3, FALSE) -> Agender | G9: =VLOOKUP(B9, customers!A:D, 4, FALSE) -> 39 | H9: =VLOOKUP(B9, customers!A:H, 8, FALSE) -> New South Wales | I9: =VLOOKUP(B9, customers!A:H, 7, FALSE) -> Amelieburgh | O9: Jun | P9: 3351443
A10: 9 | B10: 852 | C10: 12896 | D10: 44317 | E10: 44327 | F10: =VLOOKUP(B10, customers!A:D, 3, FALSE) -> Polygender | G10: =VLOOKUP(B10, customers!A:D, 4, FALSE) -> 67 | H10: =VLOOKUP(B10, customers!A:H, 8, FALSE) -> Tasmania | I10: =VLOOKUP(B10, customers!A:H, 7, FALSE) -> O'connertown | O10: Jul | P10: 3588328
A11: 10 | B11: 659 | C11: 21922 | D11: 44484 | E11: 44485 | F11: =VLOOKUP(B11, customers!A:D, 3, FALSE) -> Non-binary | G11: =VLOOKUP(B11, customers!A:D, 4, FALSE) -> 57 | H11: =VLOOKUP(B11, customers!A:H, 8, FALSE) -> Tasmania | I11: =VLOOKUP(B11, customers!A:H, 7, FALSE) -> Sophiemouth | O11: Aug | P11: 3822263
A12: 11 | B12: 785 | C12: 36624 | D12: 44362 | E12: 44377 | F12: =VLOOKUP(B12, customers!A:D, 3, FALSE) -> Genderfluid | G12: =VLOOKUP(B12, customers!A:D, 4, FALSE) -> 54 | H12: =VLOOKUP(B12, customers!A:H, 8, FALSE) -> Northern Territory | I12: =VLOOKUP(B12, customers!A:H, 7, FALSE) -> Port Adamburgh | O12: Sep | P12: 3173182
A13: 12 | B13: 120 | C13: 55507 | D13: 44377 | E13: 44388 | F13: =VLOOKUP(B13, customers!A:D, 3, FALSE) -> Polygender | G13: =VLOOKUP(B13, customers!A:D, 4, FALSE) -> 60 | H13: =VLOOKUP(B13, customers!A:H, 8, FALSE) -> Queensland | I13: =VLOOKUP(B13, customers!A:H, 7, FALSE) -> Carterbury | O13: Oct | P13: 2936611
A14: 13 | B14: 204 | C14: 57810 | D14: 44484 | E14: 44500 | F14: =VLOOKUP(B14, customers!A:D, 3, FALSE) -> Female | G14: =VLOOKUP(B14, customers!A:D, 4, FALSE) -> 60 | H14: =VLOOKUP(B14, customers!A:H, 8, FALSE) -> New South Wales | I14: =VLOOKUP(B14, customers!A:H, 7, FALSE) -> East Jakeberg | O14: Grand Total | P14: 33972936
A15: 14 | B15: 957 | C15: 21270 | D15: 44284 | E15: 44298 | F15: =VLOOKUP(B15, customers!A:D, 3, FALSE) -> Male | G15: =VLOOKUP(B15, customers!A:D, 4, FALSE) -> 75 | H15: =VLOOKUP(B15, customers!A:H, 8, FALSE) -> South Australia | I15: =VLOOKUP(B15, customers!A:H, 7, FALSE) -> Samanthaberg
A16: 15 | B16: 468 | C16: 15488 | D16: 44461 | E16: 44477 | F16: =VLOOKUP(B16, customers!A:D, 3, FALSE) -> Genderqueer | G16: =VLOOKUP(B16, customers!A:D, 4, FALSE) -> 67 | H16: =VLOOKUP(B16, customers!A:H, 8, FALSE) -> Tasmania | I16: =VLOOKUP(B16, customers!A:H, 7, FALSE) -> West Isla
A17: 16 | B17: 564 | C17: 36479 | D17: 44384 | E17: 44385 | F17: =VLOOKUP(B17, customers!A:D, 3, FALSE) -> Bigender | G17: =VLOOKUP(B17, customers!A:D, 4, FALSE) -> 34 | H17: =VLOOKUP(B17, customers!A:H, 8, FALSE) -> Northern Territory | I17: =VLOOKUP(B17, customers!A:H, 7, FALSE) -> North Marcusland
A18: 17 | B18: 614 | C18: 51822 | D18: 44236 | E18: 44238 | F18: =VLOOKUP(B18, customers!A:D, 3, FALSE) -> Polygender | G18: =VLOOKUP(B18, customers!A:D, 4, FALSE) -> 45 | H18: =VLOOKUP(B18, customers!A:H, 8, FALSE) -> New South Wales | I18: =VLOOKUP(B18, customers!A:H, 7, FALSE) -> Samuelside
A19: 18 | B19: 299 | C19: 22902 | D19: 44197 | E19: 44199 | F19: =VLOOKUP(B19, customers!A:D, 3, FALSE) -> Non-binary | G19: =VLOOKUP(B19, customers!A:D, 4, FALSE) -> 32 | H19: =VLOOKUP(B19, customers!A:H, 8, FALSE) -> Victoria | I19: =VLOOKUP(B19, customers!A:H, 7, FALSE) -> Lake Amelia
A20: 19 | B20: 513 | C20: 56754 | D20: 44438 | E20: 44449 | F20: =VLOOKUP(B20, customers!A:D, 3, FALSE) -> Non-binary | G20: =VLOOKUP(B20, customers!A:D, 4, FALSE) -> 39 | H20: =VLOOKUP(B20, customers!A:H, 8, FALSE) -> Tasmania | I20: =VLOOKUP(B20, customers!A:H, 7, FALSE) -> Port Ali
A21: 20 | B21: 789 | C21: 45129 | D21: 44209 | E21: 44216 | F21: =VLOOKUP(B21, customers!A:D, 3, FALSE) -> Genderqueer | G21: =VLOOKUP(B21, customers!A:D, 4, FALSE) -> 36 | H21: =VLOOKUP(B21, customers!A:H, 8, FALSE) -> Western Australia | I21: =VLOOKUP(B21, customers!A:H, 7, FALSE) -> Aliceland | O21: Gender | P21: AVERAGE of payment
A22: 21 | B22: 124 | C22: 11261 | D22: 44290 | E22: 44303 | F22: =VLOOKUP(B22, customers!A:D, 3, FALSE) -> Non-binary | G22: =VLOOKUP(B22, customers!A:D, 4, FALSE) -> 54 | H22: =VLOOKUP(B22, customers!A:H, 8, FALSE) -> New South Wales | I22: =VLOOKUP(B22, customers!A:H, 7, FALSE) -> Donnellyfort | O22: Agender | P22: 34250.372
A23: 22 | B23: 180 | C23: 36088 | D23: 44344 | E23: 44356 | F23: =VLOOKUP(B23, customers!A:D, 3, FALSE) -> Genderfluid | G23: =VLOOKUP(B23, customers!A:D, 4, FALSE) -> 21 | H23: =VLOOKUP(B23, customers!A:H, 8, FALSE) -> Western Australia | I23: =VLOOKUP(B23, customers!A:H, 7, FALSE) -> Chasemouth | O23: Bigender | P23: 32459.02
A24: 23 | B24: 652 | C24: 45711 | D24: 44333 | E24: 44338 | F24: =VLOOKUP(B24, customers!A:D, 3, FALSE) -> Male | G24: =VLOOKUP(B24, customers!A:D, 4, FALSE) -> 63 | H24: =VLOOKUP(B24, customers!A:H, 8, FALSE) -> South Australia | I24: =VLOOKUP(B24, customers!A:H, 7, FALSE) -> North Isabelleside | O24: Female | P24: 35333.309
A25: 24 | B25: 469 | C25: 14566 | D25: 44443 | E25: 44459 | F25: =VLOOKUP(B25, customers!A:D, 3, FALSE) -> Female | G25: =VLOOKUP(B25, customers!A:D, 4, FALSE) -> 78 | H25: =VLOOKUP(B25, customers!A:H, 8, FALSE) -> New South Wales | I25: =VLOOKUP(B25, customers!A:H, 7, FALSE) -> Andrewborough | O25: Genderfluid | P25: 35498.058
A26: 25 | B26: 562 | C26: 47075 | D26: 44381 | E26: 44385 | F26: =VLOOKUP(B26, customers!A:D, 3, FALSE) -> Agender | G26: =VLOOKUP(B26, customers!A:D, 4, FALSE) -> 58 | H26: =VLOOKUP(B26, customers!A:H, 8, FALSE) -> Queensland | I26: =VLOOKUP(B26, customers!A:H, 7, FALSE) -> West Rubyland | O26: Genderqueer | P26: 32418.107
A27: 26 | B27: 732 | C27: 15964 | D27: 44311 | E27: 44320 | F27: =VLOOKUP(B27, customers!A:D, 3, FALSE) -> Genderfluid | G27: =VLOOKUP(B27, customers!A:D, 4, FALSE) -> 80 | H27: =VLOOKUP(B27, customers!A:H, 8, FALSE) -> Queensland | I27: =VLOOKUP(B27, customers!A:H, 7, FALSE) -> Port Aaronton | O27: Male | P27: 33627.088
A28: 27 | B28: 443 | C28: 35513 | D28: 44332 | E28: 44344 | F28: =VLOOKUP(B28, customers!A:D, 3, FALSE) -> Bigender | G28: =VLOOKUP(B28, customers!A:D, 4, FALSE) -> 49 | H28: =VLOOKUP(B28, customers!A:H, 8, FALSE) -> Victoria | I28: =VLOOKUP(B28, customers!A:H, 7, FALSE) -> Crooksshire | O28: Non-binary | P28: 32760.89
A29: 28 | B29: 206 | C29: 29968 | D29: 44427 | E29: 44443 | F29: =VLOOKUP(B29, customers!A:D, 3, FALSE) -> Polygender | G29: =VLOOKUP(B29, customers!A:D, 4, FALSE) -> 66 | H29: =VLOOKUP(B29, customers!A:H, 8, FALSE) -> Queensland | I29: =VLOOKUP(B29, customers!A:H, 7, FALSE) -> South Clairetown | O29: Polygender | P29: 34906.29
A30: 29 | B30: 993 | C30: 57645 | D30: 44277 | E30: 44283 | F30: =VLOOKUP(B30, customers!A:D, 3, FALSE) -> Polygender | G30: =VLOOKUP(B30, customers!A:D, 4, FALSE) -> 24 | H30: =VLOOKUP(B30, customers!A:H, 8, FALSE) -> Victoria | I30: =VLOOKUP(B30, customers!A:H, 7, FALSE) -> Michaelberg | O30: Grand Total | P30: 33972.936
A31: 30 | B31: 260 | C31: 59350 | D31: 44384 | E31: 44403 | F31: =VLOOKUP(B31, customers!A:D, 3, FALSE) -> Female | G31: =VLOOKUP(B31, customers!A:D, 4, FALSE) -> 27 | H31: =VLOOKUP(B31, customers!A:H, 8, FALSE) -> Tasmania | I31: =VLOOKUP(B31, customers!A:H, 7, FALSE) -> Trompview
A32: 31 | B32: 727 | C32: 15722 | D32: 44266 | E32: 44291 | F32: =VLOOKUP(B32, customers!A:D, 3, FALSE) -> Female | G32: =VLOOKUP(B32, customers!A:D, 4, FALSE) -> 26 | H32: =VLOOKUP(B32, customers!A:H, 8, FALSE) -> New South Wales | I32: =VLOOKUP(B32, customers!A:H, 7, FALSE) -> Jacobport
A33: 32 | B33: 627 | C33: 24976 | D33: 44364 | E33: 44391 | F33: =VLOOKUP(B33, customers!A:D, 3, FALSE) -> Genderfluid | G33: =VLOOKUP(B33, customers!A:D, 4, FALSE) -> 51 | H33: =VLOOKUP(B33, customers!A:H, 8, FALSE) -> South Australia | I33: =VLOOKUP(B33, customers!A:H, 7, FALSE) -> Port Christopher | O33: Age | P33: SUM of payment
A34: 33 | B34: 588 | C34: 52945 | D34: 44378 | E34: 44384 | F34: =VLOOKUP(B34, customers!A:D, 3, FALSE) -> Genderfluid | G34: =VLOOKUP(B34, customers!A:D, 4, FALSE) -> 48 | H34: =VLOOKUP(B34, customers!A:H, 8, FALSE) -> Victoria | I34: =VLOOKUP(B34, customers!A:H, 7, FALSE) -> West Danieltown | O34: 20-29 | P34: 6036758
A35: 34 | B35: 412 | C35: 36244 | D35: 44339 | E35: 44346 | F35: =VLOOKUP(B35, customers!A:D, 3, FALSE) -> Polygender | G35: =VLOOKUP(B35, customers!A:D, 4, FALSE) -> 21 | H35: =VLOOKUP(B35, customers!A:H, 8, FALSE) -> South Australia | I35: =VLOOKUP(B35, customers!A:H, 7, FALSE) -> Hackettchester | O35: 30-39 | P35: 5689910
A36: 35 | B36: 358 | C36: 49665 | D36: 44439 | E36: 44446 | F36: =VLOOKUP(B36, customers!A:D, 3, FALSE) -> Genderfluid | G36: =VLOOKUP(B36, customers!A:D, 4, FALSE) -> 64 | H36: =VLOOKUP(B36, customers!A:H, 8, FALSE) -> Northern Territory | I36: =VLOOKUP(B36, customers!A:H, 7, FALSE) -> Kreigerbury | O36: 40-49 | P36: 5598955
A37: 36 | B37: 51 | C37: 32494 | D37: 44430 | E37: 44443 | F37: =VLOOKUP(B37, customers!A:D, 3, FALSE) -> Non-binary | G37: =VLOOKUP(B37, customers!A:D, 4, FALSE) -> 52 | H37: =VLOOKUP(B37, customers!A:H, 8, FALSE) -> Northern Territory | I37: =VLOOKUP(B37, customers!A:H, 7, FALSE) -> South Evaport | O37: 50-59 | P37: 5975593
A38: 37 | B38: 78 | C38: 53949 | D38: 44384 | E38: 44395 | F38: =VLOOKUP(B38, customers!A:D, 3, FALSE) -> Genderqueer | G38: =VLOOKUP(B38, customers!A:D, 4, FALSE) -> 38 | H38: =VLOOKUP(B38, customers!A:H, 8, FALSE) -> Northern Territory | I38: =VLOOKUP(B38, customers!A:H, 7, FALSE) -> Lake Alihaven | O38: 60-69 | P38: 5244411
A39: 38 | B39: 809 | C39: 46219 | D39: 44230 | E39: 44246 | F39: =VLOOKUP(B39, customers!A:D, 3, FALSE) -> Bigender | G39: =VLOOKUP(B39, customers!A:D, 4, FALSE) -> 76 | H39: =VLOOKUP(B39, customers!A:H, 8, FALSE) -> Tasmania | I39: =VLOOKUP(B39, customers!A:H, 7, FALSE) -> South Tyler | O39: 70-79 | P39: 4963022
A40: 39 | B40: 466 | C40: 23990 | D40: 44253 | E40: 44275 | F40: =VLOOKUP(B40, customers!A:D, 3, FALSE) -> Male | G40: =VLOOKUP(B40, customers!A:D, 4, FALSE) -> 28 | H40: =VLOOKUP(B40, customers!A:H, 8, FALSE) -> South Australia | I40: =VLOOKUP(B40, customers!A:H, 7, FALSE) -> North Justin | O40: 80-90 | P40: 464287
...

Sheet products
A1: product_ID | B1: product_type | C1: product_name | D1: size | E1: colour | F1: price | G1: quantity | H1: description | I1: Total price | J1: Sales_Id | K1: Order_id | L1: Product_id | M1: Price per unit | N1: quantity | O1: order_id | P1: customer_id | Q1: payment | R1: order_date | S1: delivery_date | T1: Gender | U1: Age | V1: State | W1: customer_id | X1: customer_name
A2: 0 | B2: Shirt | C2: Oxford Cloth | D2: XS | E2: red | F2: 114 | G2: 66 | H2: A red coloured, XS sized, Oxford Cloth Shirt | I2: =VLOOKUP(A2, sales!A:F, 6,FALSE) -> 212 | J2: =VLOOKUP(A2, sales!A:F, 1,FALSE) -> 0 | K2: =VLOOKUP(A2, sales!A:F, 2,FALSE) -> 1 | L2: =VLOOKUP(A2, sales!A:F, 3,FALSE) -> 218 | M2: =VLOOKUP(A2, sales!A:F, 4,FALSE) -> 106 | N2: =VLOOKUP(A2, sales!A:F, 5,FALSE) -> 2 | O2: =VLOOKUP(K2, orders!A:I, 1,FALSE) -> 1 | P2: =VLOOKUP(K2, orders!A:I, 2,FALSE) -> 64 | Q2: =VLOOKUP(K2, orders!A:I, 3,FALSE) -> 30811 | R2: =VLOOKUP(K2, orders!A:I, 4,FALSE) -> 44438 | S2: =VLOOKUP(K2, orders!A:I, 5,FALSE) -> 44463 | T2: =VLOOKUP(K2, orders!A:I, 6,FALSE) -> Genderfluid | U2: =VLOOKUP(K2, orders!A:I, 7,FALSE) -> 75 | V2: =VLOOKUP(K2, orders!A:I, 8,FALSE) -> South Australia | W2: =VLOOKUP(P2, customers!A:D, 1, FALSE) -> 64 | X2: =VLOOKUP(P2, customers!A:D, 2, FALSE) -> Annabella Devote
A3: 1 | B3: Shirt | C3: Oxford Cloth | D3: S | E3: red | F3: 114 | G3: 53 | H3: A red coloured, S sized, Oxford Cloth Shirt | I3: =VLOOKUP(A3, sales!A:F, 6,FALSE) -> 118 | J3: =VLOOKUP(A3, sales!A:F, 1,FALSE) -> 1 | K3: =VLOOKUP(A3, sales!A:F, 2,FALSE) -> 1 | L3: =VLOOKUP(A3, sales!A:F, 3,FALSE) -> 481 | M3: =VLOOKUP(A3, sales!A:F, 4,FALSE) -> 118 | N3: =VLOOKUP(A3, sales!A:F, 5,FALSE) -> 1 | O3: =VLOOKUP(K3, orders!A:I, 1,FALSE) -> 1 | P3: =VLOOKUP(K3, orders!A:I, 2,FALSE) -> 64 | Q3: =VLOOKUP(K3, orders!A:I, 3,FALSE) -> 30811 | R3: =VLOOKUP(K3, orders!A:I, 4,FALSE) -> 44438 | S3: =VLOOKUP(K3, orders!A:I, 5,FALSE) -> 44463 | T3: =VLOOKUP(K3, orders!A:I, 6,FALSE) -> Genderfluid | U3: =VLOOKUP(K3, orders!A:I, 7,FALSE) -> 75 | V3: =VLOOKUP(K3, orders!A:I, 8,FALSE) -> South Australia | W3: =VLOOKUP(P3, customers!A:D, 1, FALSE) -> 64 | X3: =VLOOKUP(P3, customers!A:D, 2, FALSE) -> Annabella Devote
A4: 2 | B4: Shirt | C4: Oxford Cloth | D4: M | E4: red | F4: 114 | G4: 54 | H4: A red coloured, M sized, Oxford Cloth Shirt | I4: =VLOOKUP(A4, sales!A:F, 6,FALSE) -> 288 | J4: =VLOOKUP(A4, sales!A:F, 1,FALSE) -> 2 | K4: =VLOOKUP(A4, sales!A:F, 2,FALSE) -> 1 | L4: =VLOOKUP(A4, sales!A:F, 3,FALSE) -> 2 | M4: =VLOOKUP(A4, sales!A:F, 4,FALSE) -> 96 | N4: =VLOOKUP(A4, sales!A:F, 5,FALSE) -> 3 | O4: =VLOOKUP(K4, orders!A:I, 1,FALSE) -> 1 | P4: =VLOOKUP(K4, orders!A:I, 2,FALSE) -> 64 | Q4: =VLOOKUP(K4, orders!A:I, 3,FALSE) -> 30811 | R4: =VLOOKUP(K4, orders!A:I, 4,FALSE) -> 44438 | S4: =VLOOKUP(K4, orders!A:I, 5,FALSE) -> 44463 | T4: =VLOOKUP(K4, orders!A:I, 6,FALSE) -> Genderfluid | U4: =VLOOKUP(K4, orders!A:I, 7,FALSE) -> 75 | V4: =VLOOKUP(K4, orders!A:I, 8,FALSE) -> South Australia | W4: =VLOOKUP(P4, customers!A:D, 1, FALSE) -> 64 | X4: =VLOOKUP(P4, customers!A:D, 2, FALSE) -> Annabella Devote
A5: 3 | B5: Shirt | C5: Oxford Cloth | D5: L | E5: red | F5: 114 | G5: 69 | H5: A red coloured, L sized, Oxford Cloth Shirt | I5: =VLOOKUP(A5, sales!A:F, 6,FALSE) -> 212 | J5: =VLOOKUP(A5, sales!A:F, 1,FALSE) -> 3 | K5: =VLOOKUP(A5, sales!A:F, 2,FALSE) -> 1 | L5: =VLOOKUP(A5, sales!A:F, 3,FALSE) -> 1002 | M5: =VLOOKUP(A5, sales!A:F, 4,FALSE) -> 106 | N5: =VLOOKUP(A5, sales!A:F, 5,FALSE) -> 2 | O5: =VLOOKUP(K5, orders!A:I, 1,FALSE) -> 1 | P5: =VLOOKUP(K5, orders!A:I, 2,FALSE) -> 64 | Q5: =VLOOKUP(K5, orders!A:I, 3,FALSE) -> 30811 | R5: =VLOOKUP(K5, orders!A:I, 4,FALSE) -> 44438 | S5: =VLOOKUP(K5, orders!A:I, 5,FALSE) -> 44463 | T5: =VLOOKUP(K5, orders!A:I, 6,FALSE) -> Genderfluid | U5: =VLOOKUP(K5, orders!A:I, 7,FALSE) -> 75 | V5: =VLOOKUP(K5, orders!A:I, 8,FALSE) -> South Australia | W5: =VLOOKUP(P5, customers!A:D, 1, FALSE) -> 64 | X5: =VLOOKUP(P5, customers!A:D, 2, FALSE) -> Annabella Devote
A6: 4 | B6: Shirt | C6: Oxford Cloth | D6: XL | E6: red | F6: 114 | G6: 47 | H6: A red coloured, XL sized, Oxford Cloth Shirt | I6: =VLOOKUP(A6, sales!A:F, 6,FALSE) -> 339 | J6: =VLOOKUP(A6, sales!A:F, 1,FALSE) -> 4 | K6: =VLOOKUP(A6, sales!A:F, 2,FALSE) -> 1 | L6: =VLOOKUP(A6, sales!A:F, 3,FALSE) -> 691 | M6: =VLOOKUP(A6, sales!A:F, 4,FALSE) -> 113 | N6: =VLOOKUP(A6, sales!A:F, 5,FALSE) -> 3 | O6: =VLOOKUP(K6, orders!A:I, 1,FALSE) -> 1 | P6: =VLOOKUP(K6, orders!A:I, 2,FALSE) -> 64 | Q6: =VLOOKUP(K6, orders!A:I, 3,FALSE) -> 30811 | R6: =VLOOKUP(K6, orders!A:I, 4,FALSE) -> 44438 | S6: =VLOOKUP(K6, orders!A:I, 5,FALSE) -> 44463 | T6: =VLOOKUP(K6, orders!A:I, 6,FALSE) -> Genderfluid | U6: =VLOOKUP(K6, orders!A:I, 7,FALSE) -> 75 | V6: =VLOOKUP(K6, orders!A:I, 8,FALSE) -> South Australia | W6: =VLOOKUP(P6, customers!A:D, 1, FALSE) -> 64 | X6: =VLOOKUP(P6, customers!A:D, 2, FALSE) -> Annabella Devote
A7: 5 | B7: Shirt | C7: Oxford Cloth | D7: XS | E7: orange | F7: 114 | G7: 45 | H7: A orange coloured, XS sized, Oxford Cloth Shirt | I7: =VLOOKUP(A7, sales!A:F, 6,FALSE) -> 318 | J7: =VLOOKUP(A7, sales!A:F, 1,FALSE) -> 5 | K7: =VLOOKUP(A7, sales!A:F, 2,FALSE) -> 1 | L7: =VLOOKUP(A7, sales!A:F, 3,FALSE) -> 981 | M7: =VLOOKUP(A7, sales!A:F, 4,FALSE) -> 106 | N7: =VLOOKUP(A7, sales!A:F, 5,FALSE) -> 3 | O7: =VLOOKUP(K7, orders!A:I, 1,FALSE) -> 1 | P7: =VLOOKUP(K7, orders!A:I, 2,FALSE) -> 64 | Q7: =VLOOKUP(K7, orders!A:I, 3,FALSE) -> 30811 | R7: =VLOOKUP(K7, orders!A:I, 4,FALSE) -> 44438 | S7: =VLOOKUP(K7, orders!A:I, 5,FALSE) -> 44463 | T7: =VLOOKUP(K7, orders!A:I, 6,FALSE) -> Genderfluid | U7: =VLOOKUP(K7, orders!A:I, 7,FALSE) -> 75 | V7: =VLOOKUP(K7, orders!A:I, 8,FALSE) -> South Australia | W7: =VLOOKUP(P7, customers!A:D, 1, FALSE) -> 64 | X7: =VLOOKUP(P7, customers!A:D, 2, FALSE) -> Annabella Devote
A8: 6 | B8: Shirt | C8: Oxford Cloth | D8: S | E8: orange | F8: 114 | G8: 72 | H8: A orange coloured, S sized, Oxford Cloth Shirt | I8: =VLOOKUP(A8, sales!A:F, 6,FALSE) -> 96 | J8: =VLOOKUP(A8, sales!A:F, 1,FALSE) -> 6 | K8: =VLOOKUP(A8, sales!A:F, 2,FALSE) -> 2 | L8: =VLOOKUP(A8, sales!A:F, 3,FALSE) -> 915 | M8: =VLOOKUP(A8, sales!A:F, 4,FALSE) -> 96 | N8: =VLOOKUP(A8, sales!A:F, 5,FALSE) -> 1 | O8: =VLOOKUP(K8, orders!A:I, 1,FALSE) -> 2 | P8: =VLOOKUP(K8, orders!A:I, 2,FALSE) -> 473 | Q8: =VLOOKUP(K8, orders!A:I, 3,FALSE) -> 50490 | R8: =VLOOKUP(K8, orders!A:I, 4,FALSE) -> 44230 | S8: =VLOOKUP(K8, orders!A:I, 5,FALSE) -> 44240 | T8: =VLOOKUP(K8, orders!A:I, 6,FALSE) -> Male | U8: =VLOOKUP(K8, orders!A:I, 7,FALSE) -> 61 | V8: =VLOOKUP(K8, orders!A:I, 8,FALSE) -> South Australia | W8: =VLOOKUP(P8, customers!A:D, 1, FALSE) -> 473 | X8: =VLOOKUP(P8, customers!A:D, 2, FALSE) -> Lori Briars
A9: 7 | B9: Shirt | C9: Oxford Cloth | D9: M | E9: orange | F9: 114 | G9: 77 | H9: A orange coloured, M sized, Oxford Cloth Shirt | I9: =VLOOKUP(A9, sales!A:F, 6,FALSE) -> 113 | J9: =VLOOKUP(A9, sales!A:F, 1,FALSE) -> 7 | K9: =VLOOKUP(A9, sales!A:F, 2,FALSE) -> 2 | L9: =VLOOKUP(A9, sales!A:F, 3,FALSE) -> 686 | M9: =VLOOKUP(A9, sales!A:F, 4,FALSE) -> 113 | N9: =VLOOKUP(A9, sales!A:F, 5,FALSE) -> 1 | O9: =VLOOKUP(K9, orders!A:I, 1,FALSE) -> 2 | P9: =VLOOKUP(K9, orders!A:I, 2,FALSE) -> 473 | Q9: =VLOOKUP(K9, orders!A:I, 3,FALSE) -> 50490 | R9: =VLOOKUP(K9, orders!A:I, 4,FALSE) -> 44230 | S9: =VLOOKUP(K9, orders!A:I, 5,FALSE) -> 44240 | T9: =VLOOKUP(K9, orders!A:I, 6,FALSE) -> Male | U9: =VLOOKUP(K9, orders!A:I, 7,FALSE) -> 61 | V9: =VLOOKUP(K9, orders!A:I, 8,FALSE) -> South Australia | W9: =VLOOKUP(P9, customers!A:D, 1, FALSE) -> 473 | X9: =VLOOKUP(P9, customers!A:D, 2, FALSE) -> Lori Briars
A10: 8 | B10: Shirt | C10: Oxford Cloth | D10: L | E10: orange | F10: 114 | G10: 48 | H10: A orange coloured, L sized, Oxford Cloth Shirt | I10: =VLOOKUP(A10, sales!A:F, 6,FALSE) -> 345 | J10: =VLOOKUP(A10, sales!A:F, 1,FALSE) -> 8 | K10: =VLOOKUP(A10, sales!A:F, 2,FALSE) -> 2 | L10: =VLOOKUP(A10, sales!A:F, 3,FALSE) -> 1091 | M10: =VLOOKUP(A10, sales!A:F, 4,FALSE) -> 115 | N10: =VLOOKUP(A10, sales!A:F, 5,FALSE) -> 3 | O10: =VLOOKUP(K10, orders!A:I, 1,FALSE) -> 2 | P10: =VLOOKUP(K10, orders!A:I, 2,FALSE) -> 473 | Q10: =VLOOKUP(K10, orders!A:I, 3,FALSE) -> 50490 | R10: =VLOOKUP(K10, orders!A:I, 4,FALSE) -> 44230 | S10: =VLOOKUP(K10, orders!A:I, 5,FALSE) -> 44240 | T10: =VLOOKUP(K10, orders!A:I, 6,FALSE) -> Male | U10: =VLOOKUP(K10, orders!A:I, 7,FALSE) -> 61 | V10: =VLOOKUP(K10, orders!A:I, 8,FALSE) -> South Australia | W10: =VLOOKUP(P10, customers!A:D, 1, FALSE) -> 473 | X10: =VLOOKUP(P10, customers!A:D, 2, FALSE) -> Lori Briars
A11: 9 | B11: Shirt | C11: Oxford Cloth | D11: XL | E11: orange | F11: 114 | G11: 43 | H11: A orange coloured, XL sized, Oxford Cloth Shirt | I11: =VLOOKUP(A11, sales!A:F, 6,FALSE) -> 105 | J11: =VLOOKUP(A11, sales!A:F, 1,FALSE) -> 9 | K11: =VLOOKUP(A11, sales!A:F, 2,FALSE) -> 2 | L11: =VLOOKUP(A11, sales!A:F, 3,FALSE) -> 1196 | M11: =VLOOKUP(A11, sales!A:F, 4,FALSE) -> 105 | N11: =VLOOKUP(A11, sales!A:F, 5,FALSE) -> 1 | O11: =VLOOKUP(K11, orders!A:I, 1,FALSE) -> 2 | P11: =VLOOKUP(K11, orders!A:I, 2,FALSE) -> 473 | Q11: =VLOOKUP(K11, orders!A:I, 3,FALSE) -> 50490 | R11: =VLOOKUP(K11, orders!A:I, 4,FALSE) -> 44230 | S11: =VLOOKUP(K11, orders!A:I, 5,FALSE) -> 44240 | T11: =VLOOKUP(K11, orders!A:I, 6,FALSE) -> Male | U11: =VLOOKUP(K11, orders!A:I, 7,FALSE) -> 61 | V11: =VLOOKUP(K11, orders!A:I, 8,FALSE) -> South Australia | W11: =VLOOKUP(P11, customers!A:D, 1, FALSE) -> 473 | X11: =VLOOKUP(P11, customers!A:D, 2, FALSE) -> Lori Briars
A12: 10 | B12: Shirt | C12: Oxford Cloth | D12: XS | E12: yellow | F12: 114 | G12: 72 | H12: A yellow coloured, XS sized, Oxford Cloth Shirt | I12: =VLOOKUP(A12, sales!A:F, 6,FALSE) -> 273 | J12: =VLOOKUP(A12, sales!A:F, 1,FALSE) -> 10 | K12: =VLOOKUP(A12, sales!A:F, 2,FALSE) -> 2 | L12: =VLOOKUP(A12, sales!A:F, 3,FALSE) -> 157 | M12: =VLOOKUP(A12, sales!A:F, 4,FALSE) -> 91 | N12: =VLOOKUP(A12, sales!A:F, 5,FALSE) -> 3 | O12: =VLOOKUP(K12, orders!A:I, 1,FALSE) -> 2 | P12: =VLOOKUP(K12, orders!A:I, 2,FALSE) -> 473 | Q12: =VLOOKUP(K12, orders!A:I, 3,FALSE) -> 50490 | R12: =VLOOKUP(K12, orders!A:I, 4,FALSE) -> 44230 | S12: =VLOOKUP(K12, orders!A:I, 5,FALSE) -> 44240 | T12: =VLOOKUP(K12, orders!A:I, 6,FALSE) -> Male | U12: =VLOOKUP(K12, orders!A:I, 7,FALSE) -> 61 | V12: =VLOOKUP(K12, orders!A:I, 8,FALSE) -> South Australia | W12: =VLOOKUP(P12, customers!A:D, 1, FALSE) -> 473 | X12: =VLOOKUP(P12, customers!A:D, 2, FALSE) -> Lori Briars
A13: 11 | B13: Shirt | C13: Oxford Cloth | D13: S | E13: yellow | F13: 114 | G13: 78 | H13: A yellow coloured, S sized, Oxford Cloth Shirt | I13: =VLOOKUP(A13, sales!A:F, 6,FALSE) -> 198 | J13: =VLOOKUP(A13, sales!A:F, 1,FALSE) -> 11 | K13: =VLOOKUP(A13, sales!A:F, 2,FALSE) -> 2 | L13: =VLOOKUP(A13, sales!A:F, 3,FALSE) -> 1174 | M13: =VLOOKUP(A13, sales!A:F, 4,FALSE) -> 99 | N13: =VLOOKUP(A13, sales!A:F, 5,FALSE) -> 2 | O13: =VLOOKUP(K13, orders!A:I, 1,FALSE) -> 2 | P13: =VLOOKUP(K13, orders!A:I, 2,FALSE) -> 473 | Q13: =VLOOKUP(K13, orders!A:I, 3,FALSE) -> 50490 | R13: =VLOOKUP(K13, orders!A:I, 4,FALSE) -> 44230 | S13: =VLOOKUP(K13, orders!A:I, 5,FALSE) -> 44240 | T13: =VLOOKUP(K13, orders!A:I, 6,FALSE) -> Male | U13: =VLOOKUP(K13, orders!A:I, 7,FALSE) -> 61 | V13: =VLOOKUP(K13, orders!A:I, 8,FALSE) -> South Australia | W13: =VLOOKUP(P13, customers!A:D, 1, FALSE) -> 473 | X13: =VLOOKUP(P13, customers!A:D, 2, FALSE) -> Lori Briars
... A1261: 1259 | B1261: Trousers | C1261: Tracksuit Bottoms | D1261: XL | E1261: violet | F1261: 91 | G1261: 60 | H1261: A violet coloured, XL sized, Tracksuit Bottoms Trousers | I1261: =VLOOKUP(A1261, sales!A:F, 6,FALSE) -> 100 | J1261: =VLOOKUP(A1261, sales!A:F, 1,FALSE) -> 1259 | K1261: =VLOOKUP(A1261, sales!A:F, 2,FALSE) -> 260 | L1261: =VLOOKUP(A1261, sales!A:F, 3,FALSE) -> 563 | M1261: =VLOOKUP(A1261, sales!A:F, 4,FALSE) -> 100 | N1261: =VLOOKUP(A1261, sales!A:F, 5,FALSE) -> 1 | O1261: =VLOOKUP(K1261, orders!A:I, 1,FALSE) -> 260 | P1261: =VLOOKUP(K1261, orders!A:I, 2,FALSE) -> 317 | Q1261: =VLOOKUP(K1261, orders!A:I, 3,FALSE) -> 56068 | R1261: =VLOOKUP(K1261, orders!A:I, 4,FALSE) -> 44390 | S1261: =VLOOKUP(K1261, orders!A:I, 5,FALSE) -> 44402 | T1261: =VLOOKUP(K1261, orders!A:I, 6,FALSE) -> Male | U1261: =VLOOKUP(K1261, orders!A:I, 7,FALSE) -> 48 | V1261: =VLOOKUP(K1261, orders!A:I, 8,FALSE) -> Australian Capital Territory | W1261: =VLOOKUP(P1261, customers!A:D, 1, FALSE) -> 317 | X1261: =VLOOKUP(P1261, customers!A:D, 2, FALSE) -> Gates Torrance

Sheet sales
A1: sales_id | B1: order_id | C1: product_id | D1: price_per_unit | E1: quantity | F1: total_price | G1: Product_type | H1: Product_name | I1: Order_date
A2: 0 | B2: 1 | C2: 218 | D2: 106 | E2: 2 | F2: 212 | G2: =VLOOKUP(C2, products!A:B, 2, FALSE) -> Shirt | H2: =VLOOKUP(C2, products!A:C, 3, FALSE) -> Chambray | I2: =VLOOKUP(B2,orders!A:D, 4, FALSE) -> 44438
A3: 1 | B3: 1 | C3: 481 | D3: 118 | E3: 1 | F3: 118 | G3: =VLOOKUP(C3, products!A:B, 2, FALSE) -> Jacket | H3: =VLOOKUP(C3, products!A:C, 3, FALSE) -> Puffer | I3: =VLOOKUP(B3,orders!A:D, 4, FALSE) -> 44438
A4: 2 | B4: 1 | C4: 2 | D4: 96 | E4: 3 | F4: 288 | G4: =VLOOKUP(C4, products!A:B, 2, FALSE) -> Shirt | H4: =VLOOKUP(C4, products!A:C, 3, FALSE) -> Oxford Cloth | I4: =VLOOKUP(B4,orders!A:D, 4, FALSE) -> 44438
A5: 3 | B5: 1 | C5: 1002 | D5: 106 | E5: 2 | F5: 212 | G5: =VLOOKUP(C5, products!A:B, 2, FALSE) -> Trousers | H5: =VLOOKUP(C5, products!A:C, 3, FALSE) -> Wool | I5: =VLOOKUP(B5,orders!A:D, 4, FALSE) -> 44438
A6: 4 | B6: 1 | C6: 691 | D6: 113 | E6: 3 | F6: 339 | G6: =VLOOKUP(C6, products!A:B, 2, FALSE) -> Jacket | H6: =VLOOKUP(C6, products!A:C, 3, FALSE) -> Parka | I6: =VLOOKUP(B6,orders!A:D, 4, FALSE) -> 44438
A7: 5 | B7: 1 | C7: 981 | D7: 106 | E7: 3 | F7: 318 | G7: =VLOOKUP(C7, products!A:B, 2, FALSE) -> Trousers | H7: =VLOOKUP(C7, products!A:C, 3, FALSE) -> Wool | I7: =VLOOKUP(B7,orders!A:D, 4, FALSE) -> 44438
A8: 6 | B8: 2 | C8: 915 | D8: 96 | E8: 1 | F8: 96 | G8: =VLOOKUP(C8, products!A:B, 2, FALSE) -> Trousers | H8: =VLOOKUP(C8, products!A:C, 3, FALSE) -> Drawstring | I8: =VLOOKUP(B8,orders!A:D, 4, FALSE) -> 44230
A9: 7 | B9: 2 | C9: 686 | D9: 113 | E9: 1 | F9: 113 | G9: =VLOOKUP(C9, products!A:B, 2, FALSE) -> Jacket | H9: =VLOOKUP(C9, products!A:C, 3, FALSE) -> Parka | I9: =VLOOKUP(B9,orders!A:D, 4, FALSE) -> 44230
A10: 8 | B10: 2 | C10: 1091 | D10: 115 | E10: 3 | F10: 345 | G10: =VLOOKUP(C10, products!A:B, 2, FALSE) -> Trousers | H10: =VLOOKUP(C10, products!A:C, 3, FALSE) -> Cropped | I10: =VLOOKUP(B10,orders!A:D, 4, FALSE) -> 44230
A11: 9 | B11: 2 | C11: 1196 | D11: 105 | E11: 1 | F11: 105 | G11: =VLOOKUP(C11, products!A:B, 2, FALSE) -> Trousers | H11: =VLOOKUP(C11, products!A:C, 3, FALSE) -> Pleated | I11: =VLOOKUP(B11,orders!A:D, 4, FALSE) -> 44230
A12: 10 | B12: 2 | C12: 157 | D12: 91 | E12: 3 | F12: 273 | G12: =VLOOKUP(C12, products!A:B, 2, FALSE) -> Shirt | H12: =VLOOKUP(C12, products!A:C, 3, FALSE) -> Linen | I12: =VLOOKUP(B12,orders!A:D, 4, FALSE) -> 44230
A13: 11 | B13: 2 | C13: 1174 | D13: 99 | E13: 2 | F13: 198 | G13: =VLOOKUP(C13, products!A:B, 2, FALSE) -> Trousers | H13: =VLOOKUP(C13, products!A:C, 3, FALSE) -> High-Waisted | I13: =VLOOKUP(B13,orders!A:D, 4, FALSE) -> 44230
... A5001: 4999 | B5001: 999 | C5001: 1105 | D5001: 115 | E5001: 1 | F5001: 115 | G5001: =VLOOKUP(C5001, products!A:B, 2, FALSE) -> Trousers | H5001: =VLOOKUP(C5001, products!A:C, 3, FALSE) -> Cropped | I5001: =VLOOKUP(B5001,orders!A:D, 4, FALSE) -> 44362

Sheet analysis
A2: Product_type | B2: SUM of quantity | C2: SUM of total_price
A3: Jacket | B3: 3343 | C3: 357026
A4: Shirt | B4: 3259 | C4: 333600
A5: Trousers | B5: 3360 | C5: 341174
A6: Grand Total | B6: 9962 | C6: 1031800
A20: Orders
A25: order_date | B25: SUM of payment | K25: Age | L25: SUM of payment
A26: Jan | B26: 3520014 | K26: 20-29 | L26: 6036758
A27: Feb | B27: 3190783 | K27: 30-39 | L27: 5689910
A28: Mar | B28: 4129045 | K28: 40-49 | L28: 5598955
A29: Apr | B29: 3233260 | K29: 50-59 | L29: 5975593
A30: May | B30: 3028007 | K30: 60-69 | L30: 5244411
A31: Jun | B31: 3351443 | K31: 70-79 | L31: 4963022
A32: Jul | B32: 3588328 | K32: 80-90 | L32: 464287
A33: Aug | B33: 3822263 | K33: Grand Total | L33: 33972936
A34: Sep | B34: 3173182
A35: Oct | B35: 2936611
A36: Grand Total | B36: 33972936
J46: State | K46: Age | L46: SUM of payment
A47: State | B47: COUNTA of order_date | J47: Australian Capital Territory | K47: 20-29 | L47: 607998
A48: Australian Capital Territory | B48: 118 | K48: 30-39 | L48: 659362
A49: New South Wales | B49: 129 | K49: 40-49 | L49: 695165
A50: Northern Territory | B50: 106 | K50: 50-59 | L50: 1064525
A51: Queensland | B51: 139 | K51: 60-69 | L51: 557085
A52: South Australia | B52: 148 | K52: 70-79 | L52: 428996
A53: Tasmania | B53: 112 | J53: Australian Capital Territory Total | L53: 4013131
A54: Victoria | B54: 118 | J54: New South Wales | K54: 20-29 | L54: 712943
A55: Western Australia | B55: 130 | K55: 30-39 | L55: 447464
A56: Grand Total | B56: 1000 | K56: 40-49 | L56: 419263
K57: 50-59 | L57: 716560
K58: 60-69 | L58: 666869
K59: 70-79 | L59: 1083413
K60: 80-90 | L60: 226350
J61: New South Wales Total | L61: 4272862
J62: Northern Territory | K62: 20-29 | L62: 510959
K63: 30-39 | L63: 749816
K64: 40-49 | L64: 491223
K65: 50-59 | L65: 947612
K66: 60-69 | L66: 577985
K67: 70-79 | L67: 479422
...

Sheet analysis2
B2: product_type | C2: Gender | D2: AVERAGE of payment | L2: Gender | M2: order_date | N2: AVERAGE of payment
B3: Jacket | C3: Agender | D3: 25703.962 | L3: Agender | M3: Jan | N3: 20046.333
C4: Bigender | D4: 28380.115 | M4: Feb | N4: 19167
C5: Female | D5: 35396.74 | M5: Mar | N5: 25106.056
C6: Genderfluid | D6: 43047.594 | M6: Apr | N6: 32851.536
C7: Genderqueer | D7: 31253.741 | M7: May | N7: 32820
C8: Male | D8: 36866.483 | M8: Jun | N8: 38201.629
C9: Non-binary | D9: 34155.694 | M9: Jul | N9: 27650.5
C10: Polygender | D10: 32985.333 | M10: Aug | N10: 32128
B11: Jacket Total | D11: 33959.314 | M11: Sep | N11: 35646.429
B12: Shirt | C12: Agender | D12: 27131.848 | L12: Agender Total | N12: 31672.711
C13: Bigender | D13: 32684.514 | L13: Bigender | M13: Jan | N13: 43897.714
C14: Female | D14: 35706.562 | M14: Feb | N14: 37532.944
C15: Genderfluid | D15: 34378.3 | M15: Mar | N15: 14719
C16: Genderqueer | D16: 37971.8 | M16: Apr | N16: 45677.5
C17: Male | D17: 32589.837 | M17: May | N17: 33404.625
C18: Non-binary | D18: 37002.66 | M18: Jun | N18: 23853
C19: Polygender | D19: 37343.651 | M19: Jul | N19: 29420.429
B20: Shirt Total | D20: 34548.317 | M20: Aug | N20: 38341
B21: Trousers | C21: Agender | D21: 39746.807 | M21: Sep | N21: 20215.667
C22: Bigender | D22: 36401.244 | M22: Oct | N22: 40783.125
C23: Female | D23: 32578.762 | F23: Looking at things in gender (big picture) | L23: Bigender Total | N23: 32349.746
C24: Genderfluid | D24: 34329.714 | F24: Looking into product name | L24: Female | M24: Feb | N24: 35106.8
C25: Genderqueer | D25: 32802.024 | F25: Color trendy in the summer | M25: Mar | N25: 29627.5
C26: Male | D26: 34222.479 | F26: Size | M26: May | N26: 23715.917
C27: Non-binary | D27: 39119.731 | F27: After this | M27: Jun | N27: 31767.947
C28: Polygender | D28: 32352.143 | F28: Go into territory location | M28: Jul | N28: 33351.067
B29: Trousers Total | D29: 35480.126 | M29: Aug | N29: 36749.308
B30: Grand Total | D30: 34662.586 | F30: data science solution | H30: relationships | M30: Sep | N30: 15419
H31: customer segmentation | M31: Oct | N31: 50725.955
L32: Female Total | N32: 34657.571
L33: Genderfluid | M33: Jan | N33: 36289.82
M34: Feb | N34: 28785.083
M35: Mar | N35: 48894
M36: Apr | N36: 27537.045
M37: May | N37: 42982
M38: Jun | N38: 35711.818
M39: Jul | N39: 44961.655
M40: Aug | N40: 44414.182
M41: Sep | N41: 43124.667
...
